<sdf version='1.6'>
  <world name='default'>
    <gui fullscreen='0'>
      <camera name='user_camera'>
        <pose frame=''>-0.107641 -0.630238 12.4392 3.14159 1.57079 3.14159</pose>
        <view_controller>orbit</view_controller>
        <projection_type>perspective</projection_type>
      </camera>
    </gui>
    <physics name='default_physics' default='0' type='ode'>
      <ode>
        <solver>
          <type>quick</type>
          <iters>20</iters>
          <sor>1</sor>
          <use_dynamic_moi_rescaling>0</use_dynamic_moi_rescaling>
        </solver>
        <constraints>
          <cfm>0</cfm>
          <erp>0.2</erp>
          <contact_max_correcting_vel>100</contact_max_correcting_vel>
          <contact_surface_layer>0</contact_surface_layer>
        </constraints>
      </ode>
      <max_step_size>0.001</max_step_size>
      <real_time_factor>1</real_time_factor>
      <real_time_update_rate>1000</real_time_update_rate>
    </physics>
    <light name='sun' type='directional'>
      <cast_shadows>1</cast_shadows>
      <pose frame=''>0 0 10 0 -0 0</pose>
      <diffuse>0.8 0.8 0.8 1</diffuse>
      <specular>0.2 0.2 0.2 1</specular>
      <attenuation>
        <range>1000</range>
        <constant>0.9</constant>
        <linear>0.01</linear>
        <quadratic>0.001</quadratic>
      </attenuation>
      <direction>-0.5 0.1 -0.9</direction>
    </light>
    <model name='ground_plane'>
      <static>1</static>
      <link name='link'>
        <collision name='collision'>
          <geometry>
            <plane>
              <normal>0 0 1</normal>
              <size>100 100</size>
            </plane>
          </geometry>
          <surface>
            <contact>
              <collide_bitmask>65535</collide_bitmask>
              <ode/>
            </contact>
            <friction>
              <ode>
                <mu>100</mu>
                <mu2>50</mu2>
              </ode>
              <torsional>
                <ode/>
              </torsional>
            </friction>
            <bounce/>
          </surface>
          <max_contacts>10</max_contacts>
        </collision>
        <visual name='visual'>
          <cast_shadows>0</cast_shadows>
          <geometry>
            <plane>
              <normal>0 0 1</normal>
              <size>100 100</size>
            </plane>
          </geometry>
          <material>
            <script>
              <uri>file://media/materials/scripts/gazebo.material</uri>
              <name>Gazebo/Grey</name>
            </script>
          </material>
        </visual>
        <self_collide>0</self_collide>
        <enable_wind>0</enable_wind>
        <kinematic>0</kinematic>
      </link>
    </model>
    <gravity>0 0 -9.8</gravity>
    <magnetic_field>6e-06 2.3e-05 -4.2e-05</magnetic_field>
    <atmosphere type='adiabatic'/>
    <scene>
      <ambient>0.4 0.4 0.4 1</ambient>
      <background>0.7 0.7 0.7 1</background>
      <shadows>1</shadows>
    </scene>
    <audio>
      <device>default</device>
    </audio>
    <wind/>
    <spherical_coordinates>
      <surface_model>EARTH_WGS84</surface_model>
      <latitude_deg>0</latitude_deg>
      <longitude_deg>0</longitude_deg>
      <elevation>0</elevation>
      <heading_deg>0</heading_deg>
    </spherical_coordinates>
    <model name='robot'>
      <link name='robot_base_footprint'>
        <pose frame=''>0 0 0 0 -0 0</pose>
        <inertial>
          <pose frame=''>0.007398 0.00014 0.123581 0 -0 0</pose>
          <mass>26.436</mass>
          <inertia>
            <ixx>1.4828</ixx>
            <ixy>0.00290001</ixy>
            <ixz>-0.038193</ixz>
            <iyy>7.00811</iyy>
            <iyz>-0.000641383</iyz>
            <izz>6.19236</izz>
          </inertia>
        </inertial>
        <collision name='robot_base_footprint_fixed_joint_lump__robot_base_link_collision'>
          <pose frame=''>0 0 0.11 0 -0 0</pose>
          <geometry>
            <mesh>
              <scale>1 1 1</scale>
              <uri>/home/benjamin/catkin_ws/src/summit_xl_common/summit_xl_description/meshes/bases/summit_xl_chassis_collision.dae</uri>
            </mesh>
          </geometry>
          <max_contacts>10</max_contacts>
          <surface>
            <contact>
              <ode/>
            </contact>
            <bounce/>
            <friction>
              <torsional>
                <ode/>
              </torsional>
              <ode/>
            </friction>
          </surface>
        </collision>
        <collision name='robot_base_footprint_fixed_joint_lump__robot_front_laser_base_link_collision_1'>
          <pose frame=''>0 0 0.44 0 -0 0</pose>
          <geometry>
            <box>
              <size>0.01 0.01 0.01</size>
            </box>
          </geometry>
          <max_contacts>10</max_contacts>
          <surface>
            <contact>
              <ode/>
            </contact>
            <bounce/>
            <friction>
              <torsional>
                <ode/>
              </torsional>
              <ode/>
            </friction>
          </surface>
        </collision>
        <collision name='robot_base_footprint_fixed_joint_lump__robot_front_ptz_camera_base_link_collision_2'>
          <pose frame=''>0.19 0 0.37 0 0.261799 0</pose>
          <geometry>
            <mesh>
              <scale>1 1 1</scale>
              <uri>/home/benjamin/catkin_ws/src/robotnik_sensors/meshes/axis_p5514.stl</uri>
            </mesh>
          </geometry>
          <surface>
            <contact>
              <ode/>
            </contact>
            <friction>
              <ode/>
              <torsional>
                <ode/>
              </torsional>
            </friction>
            <bounce/>
          </surface>
          <max_contacts>10</max_contacts>
        </collision>
        <collision name='robot_base_footprint_fixed_joint_lump__robot_front_rgbd_camera_link_collision_3'>
          <pose frame=''>0.324 0.012 0.282 0 -0 0</pose>
          <geometry>
            <mesh>
              <scale>1 1 1</scale>
              <uri>/home/benjamin/catkin_ws/src/robotnik_sensors/meshes/orbbec_astra.dae</uri>
            </mesh>
          </geometry>
          <surface>
            <contact>
              <ode/>
            </contact>
            <friction>
              <ode/>
              <torsional>
                <ode/>
              </torsional>
            </friction>
            <bounce/>
          </surface>
          <max_contacts>10</max_contacts>
        </collision>
        <collision name='robot_base_footprint_fixed_joint_lump__robot_gps_base_link_collision_4'>
          <pose frame=''>-0.22 0 0.385 0 -0 0</pose>
          <geometry>
            <mesh>
              <scale>1 1 1</scale>
              <uri>/home/benjamin/catkin_ws/src/robotnik_sensors/meshes/antenna_3GO16.stl</uri>
            </mesh>
          </geometry>
          <surface>
            <contact>
              <ode/>
            </contact>
            <friction>
              <ode/>
              <torsional>
                <ode/>
              </torsional>
            </friction>
            <bounce/>
          </surface>
          <max_contacts>10</max_contacts>
        </collision>
        <visual name='robot_base_footprint_visual'>
          <pose frame=''>0 0 0 0 -0 0</pose>
          <geometry>
            <box>
              <size>0.001 0.001 0.001</size>
            </box>
          </geometry>
        </visual>
        <visual name='robot_base_footprint_fixed_joint_lump__robot_base_link_visual_1'>
          <pose frame=''>0 0 0.11 0 -0 0</pose>
          <geometry>
            <mesh>
              <scale>1 1 1</scale>
              <uri>/home/benjamin/catkin_ws/src/summit_xl_common/summit_xl_description/meshes/bases/summit_xl_chassis.dae</uri>
            </mesh>
          </geometry>
        </visual>
        <visual name='robot_base_footprint_fixed_joint_lump__robot_front_laser_base_link_visual_2'>
          <pose frame=''>0 0 0.44 0 -0 0</pose>
          <geometry>
            <mesh>
              <scale>1 1 1</scale>
              <uri>/home/benjamin/catkin_ws/src/robotnik_sensors/meshes/hokuyo_ust_10lx.dae</uri>
            </mesh>
          </geometry>
        </visual>
        <visual name='robot_base_footprint_fixed_joint_lump__robot_front_ptz_camera_base_link_visual_3'>
          <pose frame=''>0.19 0 0.37 0 0.261799 0</pose>
          <geometry>
            <mesh>
              <scale>1 1 1</scale>
              <uri>/home/benjamin/catkin_ws/src/robotnik_sensors/meshes/axis_p5514.stl</uri>
            </mesh>
          </geometry>
          <material>
            <script>
              <name>Gazebo/FlatBlack</name>
              <uri>file://media/materials/scripts/gazebo.material</uri>
            </script>
          </material>
        </visual>
        <visual name='robot_base_footprint_fixed_joint_lump__robot_front_rgbd_camera_link_visual_4'>
          <pose frame=''>0.324 0.012 0.282 0 -0 0</pose>
          <geometry>
            <mesh>
              <scale>1 1 1</scale>
              <uri>/home/benjamin/catkin_ws/src/robotnik_sensors/meshes/orbbec_astra.dae</uri>
            </mesh>
          </geometry>
          <material>
            <script>
              <uri>__default__</uri>
              <name>__default__</name>
            </script>
          </material>
        </visual>
        <visual name='robot_base_footprint_fixed_joint_lump__robot_gps_base_link_visual_5'>
          <pose frame=''>-0.22 0 0.385 0 -0 0</pose>
          <geometry>
            <mesh>
              <scale>1 1 1</scale>
              <uri>/home/benjamin/catkin_ws/src/robotnik_sensors/meshes/antenna_3GO16.stl</uri>
            </mesh>
          </geometry>
          <material>
            <script>
              <name>Gazebo/White</name>
              <uri>file://media/materials/scripts/gazebo.material</uri>
            </script>
          </material>
        </visual>
        <visual name='robot_base_footprint_fixed_joint_lump__robot_imu_link_visual_6'>
          <pose frame=''>-0.18 0 0.28 0 -0 0</pose>
          <geometry>
            <box>
              <size>0.001 0.001 0.001</size>
            </box>
          </geometry>
          <material>
            <script>
              <uri>__default__</uri>
              <name>__default__</name>
            </script>
          </material>
        </visual>
        <velocity_decay/>
        <sensor name='robot_front_laser_sensor' type='ray'>
          <visualize>0</visualize>
          <update_rate>40</update_rate>
          <ray>
            <scan>
              <horizontal>
                <samples>1081</samples>
                <resolution>1</resolution>
                <min_angle>-2.3562</min_angle>
                <max_angle>2.3562</max_angle>
              </horizontal>
              <vertical>
                <samples>1</samples>
                <min_angle>0</min_angle>
                <max_angle>0</max_angle>
              </vertical>
            </scan>
            <range>
              <min>0.06</min>
              <max>10</max>
              <resolution>0.0043593</resolution>
            </range>
            <noise>
              <type>gaussian</type>
              <mean>0</mean>
              <stddev>0.01</stddev>
            </noise>
          </ray>
          <plugin name='robot_front_laser_controller' filename='libgazebo_ros_laser.so'>
            <topicName>front_laser/scan</topicName>
            <frameName>/robot_front_laser_link</frameName>
            <robotNamespace>/robot/</robotNamespace>
          </plugin>
          <pose frame=''>0 0 0.4874 0 -0 0</pose>
        </sensor>
        <velocity_decay/>
        <velocity_decay/>
        <sensor name='robot_front_rgbd_camera_depth_sensor' type='depth'>
          <always_on>1</always_on>
          <update_rate>20</update_rate>
          <camera name='__default__'>
            <horizontal_fov>1.0472</horizontal_fov>
            <image>
              <format>R8G8B8</format>
              <width>640</width>
              <height>480</height>
            </image>
            <clip>
              <near>0.05</near>
              <far>3.5</far>
            </clip>
          </camera>
          <plugin name='robot_front_rgbd_camera_controller' filename='libgazebo_ros_openni_kinect.so'>
            <cameraName>front_rgbd_camera</cameraName>
            <alwaysOn>1</alwaysOn>
            <updateRate>10</updateRate>
            <imageTopicName>rgb/image_raw</imageTopicName>
            <depthImageTopicName>depth/image_raw</depthImageTopicName>
            <pointCloudTopicName>depth/points</pointCloudTopicName>
            <cameraInfoTopicName>rgb/camera_info</cameraInfoTopicName>
            <depthImageCameraInfoTopicName>depth/camera_info</depthImageCameraInfoTopicName>
            <frameName>/robot_front_rgbd_camera_depth_optical_frame</frameName>
            <baseline>0.1</baseline>
            <distortion_k1>0.0</distortion_k1>
            <distortion_k2>0.0</distortion_k2>
            <distortion_k3>0.0</distortion_k3>
            <distortion_t1>0.0</distortion_t1>
            <distortion_t2>0.0</distortion_t2>
            <pointCloudCutoff>0.4</pointCloudCutoff>
            <robotNamespace>/robot/</robotNamespace>
          </plugin>
          <pose frame=''>0.324 0.012 0.282 0 -0 0</pose>
        </sensor>
        <velocity_decay/>
        <gravity>1</gravity>
        <gravity>1</gravity>
        <velocity_decay/>
        <gravity>1</gravity>
        <sensor name='robot_imu_imu_sensor' type='imu'>
          <always_on>1</always_on>
          <update_rate>100</update_rate>
          <visualize>1</visualize>
          <topic>__default_topic__</topic>
          <plugin name='robot_imu_imu_plugin' filename='libgazebo_ros_imu_sensor.so'>
            <topicName>imu/data</topicName>
            <bodyName>robot_imu_link</bodyName>
            <updateRateHZ>100.0</updateRateHZ>
            <gaussianNoise>0.0</gaussianNoise>
            <xyzOffset>0 0 0</xyzOffset>
            <rpyOffset>0 0 0</rpyOffset>
            <frameName>robot_imu_link</frameName>
            <robotNamespace>/robot/</robotNamespace>
          </plugin>
          <pose frame=''>-0.18 0 0.28 0 -0 0</pose>
          <imu/>
        </sensor>
        <self_collide>0</self_collide>
        <enable_wind>0</enable_wind>
        <kinematic>0</kinematic>
      </link>
      <link name='robot_back_left_wheel'>
        <pose frame=''>-0.229 0.235 0.11 0 -0 0</pose>
        <inertial>
          <pose frame=''>0 0 0 0 -0 0</pose>
          <mass>6.5</mass>
          <inertia>
            <ixx>0.03185</ixx>
            <ixy>0</ixy>
            <ixz>0</ixz>
            <iyy>0.039325</iyy>
            <iyz>0</iyz>
            <izz>0.03185</izz>
          </inertia>
        </inertial>
        <collision name='robot_back_left_wheel_collision'>
          <pose frame=''>0 0 0 1.5708 -0 0</pose>
          <geometry>
            <cylinder>
              <length>0.15</length>
              <radius>0.11</radius>
            </cylinder>
          </geometry>
          <surface>
            <contact>
              <ode>
                <kp>1e+07</kp>
                <kd>1</kd>
              </ode>
            </contact>
            <friction>
              <ode>
                <mu>1</mu>
                <mu2>1</mu2>
                <fdir1>1 0 0</fdir1>
              </ode>
              <torsional>
                <ode/>
              </torsional>
            </friction>
            <bounce/>
          </surface>
          <max_contacts>10</max_contacts>
        </collision>
        <visual name='robot_back_left_wheel_visual'>
          <pose frame=''>0 0 0 0 -0 0</pose>
          <geometry>
            <mesh>
              <scale>1 1 1</scale>
              <uri>/home/benjamin/catkin_ws/src/summit_xl_common/summit_xl_description/meshes/wheels/rubber_wheel_left.dae</uri>
            </mesh>
          </geometry>
          <material>
            <script>
              <uri>__default__</uri>
              <name>__default__</name>
            </script>
          </material>
        </visual>
        <gravity>1</gravity>
        <velocity_decay/>
        <self_collide>0</self_collide>
        <enable_wind>0</enable_wind>
        <kinematic>0</kinematic>
      </link>
      <joint name='robot_back_left_wheel_joint' type='revolute'>
        <child>robot_back_left_wheel</child>
        <parent>robot_base_footprint</parent>
        <axis>
          <xyz>0 1 0</xyz>
          <limit>
            <lower>-1e+16</lower>
            <upper>1e+16</upper>
          </limit>
          <dynamics>
            <spring_reference>0</spring_reference>
            <spring_stiffness>0</spring_stiffness>
          </dynamics>
          <use_parent_model_frame>1</use_parent_model_frame>
        </axis>
      </joint>
      <link name='robot_back_right_wheel'>
        <pose frame=''>-0.229 -0.235 0.11 0 -0 0</pose>
        <inertial>
          <pose frame=''>0 0 0 0 -0 0</pose>
          <mass>6.5</mass>
          <inertia>
            <ixx>0.03185</ixx>
            <ixy>0</ixy>
            <ixz>0</ixz>
            <iyy>0.039325</iyy>
            <iyz>0</iyz>
            <izz>0.03185</izz>
          </inertia>
        </inertial>
        <collision name='robot_back_right_wheel_collision'>
          <pose frame=''>0 0 0 1.5708 -0 0</pose>
          <geometry>
            <cylinder>
              <length>0.15</length>
              <radius>0.11</radius>
            </cylinder>
          </geometry>
          <surface>
            <contact>
              <ode>
                <kp>1e+07</kp>
                <kd>1</kd>
              </ode>
            </contact>
            <friction>
              <ode>
                <mu>1</mu>
                <mu2>1</mu2>
                <fdir1>1 0 0</fdir1>
              </ode>
              <torsional>
                <ode/>
              </torsional>
            </friction>
            <bounce/>
          </surface>
          <max_contacts>10</max_contacts>
        </collision>
        <visual name='robot_back_right_wheel_visual'>
          <pose frame=''>0 0 0 0 -0 0</pose>
          <geometry>
            <mesh>
              <scale>1 1 1</scale>
              <uri>/home/benjamin/catkin_ws/src/summit_xl_common/summit_xl_description/meshes/wheels/rubber_wheel_right.dae</uri>
            </mesh>
          </geometry>
          <material>
            <script>
              <uri>__default__</uri>
              <name>__default__</name>
            </script>
          </material>
        </visual>
        <gravity>1</gravity>
        <velocity_decay/>
        <self_collide>0</self_collide>
        <enable_wind>0</enable_wind>
        <kinematic>0</kinematic>
      </link>
      <joint name='robot_back_right_wheel_joint' type='revolute'>
        <child>robot_back_right_wheel</child>
        <parent>robot_base_footprint</parent>
        <axis>
          <xyz>0 1 0</xyz>
          <limit>
            <lower>-1e+16</lower>
            <upper>1e+16</upper>
          </limit>
          <dynamics>
            <spring_reference>0</spring_reference>
            <spring_stiffness>0</spring_stiffness>
          </dynamics>
          <use_parent_model_frame>1</use_parent_model_frame>
        </axis>
      </joint>
      <link name='robot_front_left_wheel'>
        <pose frame=''>0.229 0.235 0.11 0 -0 0</pose>
        <inertial>
          <pose frame=''>0 0 0 0 -0 0</pose>
          <mass>6.5</mass>
          <inertia>
            <ixx>0.03185</ixx>
            <ixy>0</ixy>
            <ixz>0</ixz>
            <iyy>0.039325</iyy>
            <iyz>0</iyz>
            <izz>0.03185</izz>
          </inertia>
        </inertial>
        <collision name='robot_front_left_wheel_collision'>
          <pose frame=''>0 0 0 1.5708 -0 0</pose>
          <geometry>
            <cylinder>
              <length>0.15</length>
              <radius>0.11</radius>
            </cylinder>
          </geometry>
          <surface>
            <contact>
              <ode>
                <kp>1e+07</kp>
                <kd>1</kd>
              </ode>
            </contact>
            <friction>
              <ode>
                <mu>1</mu>
                <mu2>1</mu2>
                <fdir1>1 0 0</fdir1>
              </ode>
              <torsional>
                <ode/>
              </torsional>
            </friction>
            <bounce/>
          </surface>
          <max_contacts>10</max_contacts>
        </collision>
        <visual name='robot_front_left_wheel_visual'>
          <pose frame=''>0 0 0 0 -0 0</pose>
          <geometry>
            <mesh>
              <scale>1 1 1</scale>
              <uri>/home/benjamin/catkin_ws/src/summit_xl_common/summit_xl_description/meshes/wheels/rubber_wheel_left.dae</uri>
            </mesh>
          </geometry>
          <material>
            <script>
              <uri>__default__</uri>
              <name>__default__</name>
            </script>
          </material>
        </visual>
        <gravity>1</gravity>
        <velocity_decay/>
        <self_collide>0</self_collide>
        <enable_wind>0</enable_wind>
        <kinematic>0</kinematic>
      </link>
      <joint name='robot_front_left_wheel_joint' type='revolute'>
        <child>robot_front_left_wheel</child>
        <parent>robot_base_footprint</parent>
        <axis>
          <xyz>0 1 0</xyz>
          <limit>
            <lower>-1e+16</lower>
            <upper>1e+16</upper>
          </limit>
          <dynamics>
            <spring_reference>0</spring_reference>
            <spring_stiffness>0</spring_stiffness>
          </dynamics>
          <use_parent_model_frame>1</use_parent_model_frame>
        </axis>
      </joint>
      <link name='robot_front_ptz_camera_pan_link'>
        <pose frame=''>0.19 0 0.37 0 0.261799 0</pose>
        <inertial>
          <pose frame=''>0 0 0 0 -0 0</pose>
          <mass>0.1</mass>
          <inertia>
            <ixx>0.000201667</ixx>
            <ixy>0</ixy>
            <ixz>0</ixz>
            <iyy>0.000184167</iyy>
            <iyz>0</iyz>
            <izz>0.000184167</izz>
          </inertia>
        </inertial>
        <self_collide>0</self_collide>
        <enable_wind>0</enable_wind>
        <kinematic>0</kinematic>
      </link>
      <joint name='robot_front_ptz_camera_pan_joint' type='revolute'>
        <child>robot_front_ptz_camera_pan_link</child>
        <parent>robot_base_footprint</parent>
        <axis>
          <xyz>-0.258819 0 -0.965926</xyz>
          <limit>
            <lower>-3.1415</lower>
            <upper>3.1415</upper>
            <effort>100</effort>
            <velocity>1</velocity>
          </limit>
          <dynamics>
            <spring_reference>0</spring_reference>
            <spring_stiffness>0</spring_stiffness>
          </dynamics>
          <use_parent_model_frame>1</use_parent_model_frame>
        </axis>
      </joint>
      <link name='robot_front_ptz_camera_tilt_link'>
        <pose frame=''>0.19 0 0.37 0 0.261799 0</pose>
        <inertial>
          <pose frame=''>0 0 0 0 -0 0</pose>
          <mass>0.3</mass>
          <inertia>
            <ixx>0.00057</ixx>
            <ixy>8.56903e-17</ixy>
            <ixz>8.56903e-17</ixz>
            <iyy>0.0005525</iyy>
            <iyz>4.1959e-28</iyz>
            <izz>0.0005875</izz>
          </inertia>
        </inertial>
        <gravity>1</gravity>
        <velocity_decay/>
        <sensor name='robot_front_ptz_camera_sensor' type='camera'>
          <update_rate>30</update_rate>
          <camera name='__default__'>
            <horizontal_fov>1.0472</horizontal_fov>
            <image>
              <format>R8G8B8</format>
              <width>640</width>
              <height>480</height>
            </image>
            <clip>
              <near>0.05</near>
              <far>8</far>
            </clip>
          </camera>
          <plugin name='robot_front_ptz_camera_controller' filename='libgazebo_ros_camera.so'>
            <alwaysOn>1</alwaysOn>
            <updateRate>0.0</updateRate>
            <cameraName>robot_front_ptz_camera</cameraName>
            <imageTopicName>image_raw</imageTopicName>
            <cameraInfoTopicName>camera_info</cameraInfoTopicName>
            <frameName>/robot_front_ptz_camera_optical_frame_link</frameName>
            <hackBaseline>0.0</hackBaseline>
            <distortionK1>0.0</distortionK1>
            <distortionK2>0.0</distortionK2>
            <distortionK3>0.0</distortionK3>
            <distortionT1>0.0</distortionT1>
            <distortionT2>0.0</distortionT2>
            <robotNamespace>/robot/</robotNamespace>
          </plugin>
          <pose frame=''>0 0 0 0 -0 0</pose>
        </sensor>
        <self_collide>0</self_collide>
        <enable_wind>0</enable_wind>
        <kinematic>0</kinematic>
      </link>
      <joint name='robot_front_ptz_camera_tilt_joint' type='revolute'>
        <child>robot_front_ptz_camera_tilt_link</child>
        <parent>robot_front_ptz_camera_pan_link</parent>
        <axis>
          <xyz>0 -1 0</xyz>
          <limit>
            <lower>-1.5708</lower>
            <upper>1.5708</upper>
            <effort>100</effort>
            <velocity>1</velocity>
          </limit>
          <dynamics>
            <spring_reference>0</spring_reference>
            <spring_stiffness>0</spring_stiffness>
          </dynamics>
          <use_parent_model_frame>1</use_parent_model_frame>
        </axis>
      </joint>
      <link name='robot_front_right_wheel'>
        <pose frame=''>0.229 -0.235 0.11 0 -0 0</pose>
        <inertial>
          <pose frame=''>0 0 0 0 -0 0</pose>
          <mass>6.5</mass>
          <inertia>
            <ixx>0.03185</ixx>
            <ixy>0</ixy>
            <ixz>0</ixz>
            <iyy>0.039325</iyy>
            <iyz>0</iyz>
            <izz>0.03185</izz>
          </inertia>
        </inertial>
        <collision name='robot_front_right_wheel_collision'>
          <pose frame=''>0 0 0 1.5708 -0 0</pose>
          <geometry>
            <cylinder>
              <length>0.15</length>
              <radius>0.11</radius>
            </cylinder>
          </geometry>
          <surface>
            <contact>
              <ode>
                <kp>1e+07</kp>
                <kd>1</kd>
              </ode>
            </contact>
            <friction>
              <ode>
                <mu>1</mu>
                <mu2>1</mu2>
                <fdir1>1 0 0</fdir1>
              </ode>
              <torsional>
                <ode/>
              </torsional>
            </friction>
            <bounce/>
          </surface>
          <max_contacts>10</max_contacts>
        </collision>
        <visual name='robot_front_right_wheel_visual'>
          <pose frame=''>0 0 0 0 -0 0</pose>
          <geometry>
            <mesh>
              <scale>1 1 1</scale>
              <uri>/home/benjamin/catkin_ws/src/summit_xl_common/summit_xl_description/meshes/wheels/rubber_wheel_right.dae</uri>
            </mesh>
          </geometry>
          <material>
            <script>
              <uri>__default__</uri>
              <name>__default__</name>
            </script>
          </material>
        </visual>
        <gravity>1</gravity>
        <velocity_decay/>
        <self_collide>0</self_collide>
        <enable_wind>0</enable_wind>
        <kinematic>0</kinematic>
      </link>
      <joint name='robot_front_right_wheel_joint' type='revolute'>
        <child>robot_front_right_wheel</child>
        <parent>robot_base_footprint</parent>
        <axis>
          <xyz>0 1 0</xyz>
          <limit>
            <lower>-1e+16</lower>
            <upper>1e+16</upper>
          </limit>
          <dynamics>
            <spring_reference>0</spring_reference>
            <spring_stiffness>0</spring_stiffness>
          </dynamics>
          <use_parent_model_frame>1</use_parent_model_frame>
        </axis>
      </joint>
      <plugin name='ros_control' filename='libgazebo_ros_control.so'>
        <robotParam>robot_description</robotParam>
        <controlPeriod>0.001</controlPeriod>
        <robotSimType>gazebo_ros_control/DefaultRobotHWSim</robotSimType>
        <legacyModeNS>1</legacyModeNS>
        <robotNamespace>/robot/</robotNamespace>
      </plugin>
      <plugin name='skid_steering' filename='libgazebo_ros_planar_move.so'>
        <commandTopic>robotnik_base_control/cmd_vel</commandTopic>
        <odometryTopic>robotnik_base_control/odom</odometryTopic>
        <odometryFrame>robot_odom</odometryFrame>
        <odometryRate>50.0</odometryRate>
        <robotBaseFrame>robot_base_footprint</robotBaseFrame>
        <publishTF>1</publishTF>
        <enableYAxis>0</enableYAxis>
        <robotNamespace>/robot/</robotNamespace>
      </plugin>
      <static>0</static>
      <plugin name='robot_gps_controller' filename='libhector_gazebo_ros_gps.so'>
        <alwaysOn>1</alwaysOn>
        <updateRate>5</updateRate>
        <frameId>robot_gps_base_link</frameId>
        <topicName>gps/fix</topicName>
        <referenceLatitude>39.5080331</referenceLatitude>
        <referenceLongitude>-0.4619816</referenceLongitude>
        <referenceHeading>90</referenceHeading>
        <velocityTopicName>gps/fix_velocity</velocityTopicName>
        <drift>0.0 0.0 0.0</drift>
        <gaussianNoise>0.00001 0.00001 0.00001</gaussianNoise>
        <velocityDrift>0.00001 0.00001 0.00001</velocityDrift>
        <velocityGaussianNoise>0.00001 0.00001 0.00001</velocityGaussianNoise>
        <robotNamespace>/robot/</robotNamespace>
        <bodyName>robot_base_footprint</bodyName>
        <xyzOffset>0.22 0 -0.385</xyzOffset>
        <rpyOffset>0 -0 0</rpyOffset>
      </plugin>
      <pose frame=''>0 0 0 0 -0 0</pose>
    </model>
    <state world_name='default'>
      <sim_time>815 107000000</sim_time>
      <real_time>673 203008252</real_time>
      <wall_time>1651587831 42075504</wall_time>
      <iterations>455756</iterations>
      <model name='ground_plane'>
        <pose frame=''>0 0 0 0 -0 0</pose>
        <scale>1 1 1</scale>
        <link name='link'>
          <pose frame=''>0 0 0 0 -0 0</pose>
          <velocity>0 0 0 0 -0 0</velocity>
          <acceleration>0 0 0 0 -0 0</acceleration>
          <wrench>0 0 0 0 -0 0</wrench>
        </link>
      </model>
      <model name='robot'>
        <pose frame=''>-2.56711 0.012295 -6e-06 0 1e-06 0.022817</pose>
        <scale>1 1 1</scale>
        <link name='robot_back_left_wheel'>
          <pose frame=''>-2.80141 0.24201 0.109994 -1e-06 0.165536 0.022817</pose>
          <velocity>1.5e-05 1e-06 4.9e-05 -8e-06 6.6e-05 1e-06</velocity>
          <acceleration>0.015493 0.00114 0.048801 -0.007855 0.066472 0.000887</acceleration>
          <wrench>0.100703 0.007413 0.317208 0 -0 0</wrench>
        </link>
        <link name='robot_back_right_wheel'>
          <pose frame=''>-2.79068 -0.227868 0.109994 -1e-06 -0.035078 0.022817</pose>
          <velocity>1.1e-05 1e-06 5e-05 -1e-05 0.000115 -1e-06</velocity>
          <acceleration>0.011 0.001076 0.049712 -0.009067 0.114811 -0.000823</acceleration>
          <wrench>0.071503 0.006996 0.323125 0 -0 0</wrench>
        </link>
        <link name='robot_base_footprint'>
          <pose frame=''>-2.56711 0.012295 -6e-06 0 1e-06 0.022817</pose>
          <velocity>7e-06 0 3.9e-05 -3e-06 4.7e-05 -4e-06</velocity>
          <acceleration>0.012974 0.000547 0.038281 0.028837 0.371233 -0.00325</acceleration>
          <wrench>0.342992 0.014451 1.01199 0 -0 0</wrench>
        </link>
        <link name='robot_front_left_wheel'>
          <pose frame=''>-2.34353 0.252459 0.109993 -2e-06 0.288859 0.022817</pose>
          <velocity>1.5e-05 0 2.7e-05 2e-06 6.6e-05 -1e-06</velocity>
          <acceleration>0.015282 4.8e-05 0.026874 0.002388 0.066169 -0.000719</acceleration>
          <wrench>0.099333 0.00031 0.174682 0 -0 0</wrench>
        </link>
        <link name='robot_front_ptz_camera_pan_link'>
          <pose frame=''>-2.37716 0.016631 0.369993 2.5e-05 -0.261803 -3.11887</pose>
          <velocity>2.3e-05 1e-06 2.9e-05 -0.000123 0.005319 -3e-06</velocity>
          <acceleration>0.02344 0.000906 0.029494 0.858639 -1.54619 -0.527886</acceleration>
          <wrench>0.002344 9.1e-05 0.002949 0 -0 0</wrench>
        </link>
        <link name='robot_front_ptz_camera_tilt_link'>
          <pose frame=''>-2.37716 0.016631 0.369993 2.5e-05 -0.170044 -3.11887</pose>
          <velocity>2.3e-05 1e-06 2.9e-05 0.022603 -0.994423 2.1e-05</velocity>
          <acceleration>0.02344 0.000906 0.029494 1.30511 -1.46154 -3.12217</acceleration>
          <wrench>0.007032 0.000272 0.008848 0 -0 0</wrench>
        </link>
        <link name='robot_front_right_wheel'>
          <pose frame=''>-2.33281 -0.217419 0.109993 -2e-06 0.105129 0.022817</pose>
          <velocity>1.3e-05 0 2.8e-05 1e-06 8.6e-05 0</velocity>
          <acceleration>0.01256 7.5e-05 0.028376 0.001256 0.086438 -0.000394</acceleration>
          <wrench>0.081642 0.000487 0.184443 0 -0 0</wrench>
        </link>
      </model>
      <model name='unit_box_'>
        <pose frame=''>3.54188 -0.003052 0.5 0 1e-06 0.00517</pose>
        <scale>1 1 1</scale>
        <link name='link'>
          <pose frame=''>3.54188 -0.003052 0.5 0 1e-06 0.00517</pose>
          <velocity>0 0 0 0 -0 0</velocity>
          <acceleration>-7.49552 -0.039228 7.63204 -2.98673 -0.564323 -3.14067</acceleration>
          <wrench>-74955.2 -392.281 76320.4 0 -0 0</wrench>
        </link>
      </model>
      <model name='unit_box_0'>
        <pose frame=''>-0.012709 3.53604 0.499996 -8e-06 -0 0.000983</pose>
        <scale>1 1 1</scale>
        <link name='link'>
          <pose frame=''>-0.012709 3.53604 0.499996 -8e-06 -0 0.000983</pose>
          <velocity>0 0 0 0 -0 0</velocity>
          <acceleration>-0.001647 1.31828 -7.64111 -2.52184 -0.004864 -0.000894</acceleration>
          <wrench>-16.4698 13182.8 -76411.1 0 -0 0</wrench>
        </link>
      </model>
      <model name='unit_box_0_clone'>
        <pose frame=''>0.015359 -3.50962 0.5 1e-06 -0 0.008212</pose>
        <scale>1 1 1</scale>
        <link name='link'>
          <pose frame=''>0.015359 -3.50962 0.5 1e-06 -0 0.008212</pose>
          <velocity>0 0 0 0 -0 0</velocity>
          <acceleration>-0.062482 7.50928 7.64141 -2.60642 -0.243545 0.000999</acceleration>
          <wrench>-624.82 75092.8 76414.1 0 -0 0</wrench>
        </link>
      </model>
      <model name='unit_box_clone1'>
        <pose frame=''>-3.56794 0.015418 0.499996 0 -8e-06 -0.003047</pose>
        <scale>1 1 1</scale>
        <link name='link'>
          <pose frame=''>-3.56794 0.015418 0.499996 0 -8e-06 -0.003047</pose>
          <velocity>0 0 0 0 -0 0</velocity>
          <acceleration>-1.3242 0.004229 -7.63199 3.12662 -0.609514 -3.14066</acceleration>
          <wrench>-13242 42.2896 -76319.9 0 -0 0</wrench>
        </link>
      </model>
      <light name='sun'>
        <pose frame=''>0 0 10 0 -0 0</pose>
      </light>
    </state>
    <model name='unit_box_0'>
      <link name='link'>
        <inertial>
          <mass>10000</mass>
          <inertia>
            <ixx>1666.67</ixx>
            <ixy>0</ixy>
            <ixz>0</ixz>
            <iyy>31490.3</iyy>
            <iyz>0</iyz>
            <izz>31490.3</izz>
          </inertia>
          <pose frame=''>0 0 0 0 -0 0</pose>
        </inertial>
        <self_collide>0</self_collide>
        <enable_wind>0</enable_wind>
        <kinematic>0</kinematic>
        <pose frame=''>0 0 0 0 -0 0</pose>
        <gravity>1</gravity>
        <visual name='visual'>
          <geometry>
            <box>
              <size>6.06534 1 1</size>
            </box>
          </geometry>
          <material>
            <script>
              <name>Gazebo/Grey</name>
              <uri>file://media/materials/scripts/gazebo.material</uri>
            </script>
            <shader type='vertex'>
              <normal_map>__default__</normal_map>
            </shader>
          </material>
          <pose frame=''>0 0 0 0 -0 0</pose>
          <transparency>0</transparency>
          <cast_shadows>1</cast_shadows>
        </visual>
        <collision name='collision'>
          <laser_retro>0</laser_retro>
          <max_contacts>10</max_contacts>
          <pose frame=''>0 0 0 0 -0 0</pose>
          <geometry>
            <box>
              <size>6.06534 1 1</size>
            </box>
          </geometry>
          <surface>
            <friction>
              <ode>
                <mu>1</mu>
                <mu2>1</mu2>
                <fdir1>0 0 0</fdir1>
                <slip1>0</slip1>
                <slip2>0</slip2>
              </ode>
              <torsional>
                <coefficient>1</coefficient>
                <patch_radius>0</patch_radius>
                <surface_radius>0</surface_radius>
                <use_patch_radius>1</use_patch_radius>
                <ode>
                  <slip>0</slip>
                </ode>
              </torsional>
            </friction>
            <bounce>
              <restitution_coefficient>0</restitution_coefficient>
              <threshold>1e+06</threshold>
            </bounce>
            <contact>
              <collide_without_contact>0</collide_without_contact>
              <collide_without_contact_bitmask>1</collide_without_contact_bitmask>
              <collide_bitmask>1</collide_bitmask>
              <ode>
                <soft_cfm>0</soft_cfm>
                <soft_erp>0.2</soft_erp>
                <kp>1e+13</kp>
                <kd>1</kd>
                <max_vel>0.01</max_vel>
                <min_depth>0</min_depth>
              </ode>
              <bullet>
                <split_impulse>1</split_impulse>
                <split_impulse_penetration_threshold>-0.01</split_impulse_penetration_threshold>
                <soft_cfm>0</soft_cfm>
                <soft_erp>0.2</soft_erp>
                <kp>1e+13</kp>
                <kd>1</kd>
              </bullet>
            </contact>
          </surface>
        </collision>
      </link>
      <static>0</static>
      <allow_auto_disable>1</allow_auto_disable>
      <pose frame=''>-0.012075 3.52302 0.499996 1e-06 1e-06 0.002251</pose>
    </model>
    <model name='unit_box_0_clone'>
      <link name='link'>
        <inertial>
          <mass>10000</mass>
          <inertia>
            <ixx>1666.67</ixx>
            <ixy>0</ixy>
            <ixz>0</ixz>
            <iyy>31490.3</iyy>
            <iyz>0</iyz>
            <izz>31490.3</izz>
          </inertia>
          <pose frame=''>0 0 0 0 -0 0</pose>
        </inertial>
        <self_collide>0</self_collide>
        <enable_wind>0</enable_wind>
        <kinematic>0</kinematic>
        <pose frame=''>0 0 0 0 -0 0</pose>
        <gravity>1</gravity>
        <visual name='visual'>
          <geometry>
            <box>
              <size>6.06534 1 1</size>
            </box>
          </geometry>
          <material>
            <script>
              <name>Gazebo/Grey</name>
              <uri>file://media/materials/scripts/gazebo.material</uri>
            </script>
            <shader type='vertex'>
              <normal_map>__default__</normal_map>
            </shader>
          </material>
          <pose frame=''>0 0 0 0 -0 0</pose>
          <transparency>0</transparency>
          <cast_shadows>1</cast_shadows>
        </visual>
        <collision name='collision'>
          <laser_retro>0</laser_retro>
          <max_contacts>10</max_contacts>
          <pose frame=''>0 0 0 0 -0 0</pose>
          <geometry>
            <box>
              <size>6.06534 1 1</size>
            </box>
          </geometry>
          <surface>
            <friction>
              <ode>
                <mu>1</mu>
                <mu2>1</mu2>
                <fdir1>0 0 0</fdir1>
                <slip1>0</slip1>
                <slip2>0</slip2>
              </ode>
              <torsional>
                <coefficient>1</coefficient>
                <patch_radius>0</patch_radius>
                <surface_radius>0</surface_radius>
                <use_patch_radius>1</use_patch_radius>
                <ode>
                  <slip>0</slip>
                </ode>
              </torsional>
            </friction>
            <bounce>
              <restitution_coefficient>0</restitution_coefficient>
              <threshold>1e+06</threshold>
            </bounce>
            <contact>
              <collide_without_contact>0</collide_without_contact>
              <collide_without_contact_bitmask>1</collide_without_contact_bitmask>
              <collide_bitmask>1</collide_bitmask>
              <ode>
                <soft_cfm>0</soft_cfm>
                <soft_erp>0.2</soft_erp>
                <kp>1e+13</kp>
                <kd>1</kd>
                <max_vel>0.01</max_vel>
                <min_depth>0</min_depth>
              </ode>
              <bullet>
                <split_impulse>1</split_impulse>
                <split_impulse_penetration_threshold>-0.01</split_impulse_penetration_threshold>
                <soft_cfm>0</soft_cfm>
                <soft_erp>0.2</soft_erp>
                <kp>1e+13</kp>
                <kd>1</kd>
              </bullet>
            </contact>
          </surface>
        </collision>
      </link>
      <static>0</static>
      <allow_auto_disable>1</allow_auto_disable>
      <pose frame=''>0.018274 -3.49124 0.5 0 -0 0.002251</pose>
    </model>
    <model name='unit_box_'>
      <link name='link'>
        <inertial>
          <mass>10000</mass>
          <inertia>
            <ixx>54847.1</ixx>
            <ixy>0</ixy>
            <ixz>0</ixz>
            <iyy>1666.67</iyy>
            <iyz>0</iyz>
            <izz>54847.1</izz>
          </inertia>
          <pose frame=''>0 0 0 0 -0 0</pose>
        </inertial>
        <self_collide>0</self_collide>
        <enable_wind>0</enable_wind>
        <kinematic>0</kinematic>
        <pose frame=''>0 0 0 0 -0 0</pose>
        <gravity>1</gravity>
        <visual name='visual'>
          <geometry>
            <box>
              <size>1 8.05087 1</size>
            </box>
          </geometry>
          <material>
            <script>
              <name>Gazebo/Grey</name>
              <uri>file://media/materials/scripts/gazebo.material</uri>
            </script>
            <shader type='vertex'>
              <normal_map>__default__</normal_map>
            </shader>
          </material>
          <pose frame=''>0 0 0 0 -0 0</pose>
          <transparency>0</transparency>
          <cast_shadows>1</cast_shadows>
        </visual>
        <collision name='collision'>
          <laser_retro>0</laser_retro>
          <max_contacts>10</max_contacts>
          <pose frame=''>0 0 0 0 -0 0</pose>
          <geometry>
            <box>
              <size>1 8.05087 1</size>
            </box>
          </geometry>
          <surface>
            <friction>
              <ode>
                <mu>1</mu>
                <mu2>1</mu2>
                <fdir1>0 0 0</fdir1>
                <slip1>0</slip1>
                <slip2>0</slip2>
              </ode>
              <torsional>
                <coefficient>1</coefficient>
                <patch_radius>0</patch_radius>
                <surface_radius>0</surface_radius>
                <use_patch_radius>1</use_patch_radius>
                <ode>
                  <slip>0</slip>
                </ode>
              </torsional>
            </friction>
            <bounce>
              <restitution_coefficient>0</restitution_coefficient>
              <threshold>1e+06</threshold>
            </bounce>
            <contact>
              <collide_without_contact>0</collide_without_contact>
              <collide_without_contact_bitmask>1</collide_without_contact_bitmask>
              <collide_bitmask>1</collide_bitmask>
              <ode>
                <soft_cfm>0</soft_cfm>
                <soft_erp>0.2</soft_erp>
                <kp>1e+13</kp>
                <kd>1</kd>
                <max_vel>0.01</max_vel>
                <min_depth>0</min_depth>
              </ode>
              <bullet>
                <split_impulse>1</split_impulse>
                <split_impulse_penetration_threshold>-0.01</split_impulse_penetration_threshold>
                <soft_cfm>0</soft_cfm>
                <soft_erp>0.2</soft_erp>
                <kp>1e+13</kp>
                <kd>1</kd>
              </bullet>
            </contact>
          </surface>
        </collision>
      </link>
      <static>0</static>
      <allow_auto_disable>1</allow_auto_disable>
      <pose frame=''>3.53704 -0.002722 0.499993 1e-06 7e-06 0.004317</pose>
    </model>
    <model name='unit_box_clone1'>
      <link name='link'>
        <inertial>
          <mass>10000</mass>
          <inertia>
            <ixx>54847.1</ixx>
            <ixy>0</ixy>
            <ixz>0</ixz>
            <iyy>1666.67</iyy>
            <iyz>0</iyz>
            <izz>54847.1</izz>
          </inertia>
          <pose frame=''>0 0 0 0 -0 0</pose>
        </inertial>
        <self_collide>0</self_collide>
        <enable_wind>0</enable_wind>
        <kinematic>0</kinematic>
        <pose frame=''>0 0 0 0 -0 0</pose>
        <gravity>1</gravity>
        <visual name='visual'>
          <geometry>
            <box>
              <size>1 8.05087 1</size>
            </box>
          </geometry>
          <material>
            <script>
              <name>Gazebo/Grey</name>
              <uri>file://media/materials/scripts/gazebo.material</uri>
            </script>
            <shader type='vertex'>
              <normal_map>__default__</normal_map>
            </shader>
          </material>
          <pose frame=''>0 0 0 0 -0 0</pose>
          <transparency>0</transparency>
          <cast_shadows>1</cast_shadows>
        </visual>
        <collision name='collision'>
          <laser_retro>0</laser_retro>
          <max_contacts>10</max_contacts>
          <pose frame=''>0 0 0 0 -0 0</pose>
          <geometry>
            <box>
              <size>1 8.05087 1</size>
            </box>
          </geometry>
          <surface>
            <friction>
              <ode>
                <mu>1</mu>
                <mu2>1</mu2>
                <fdir1>0 0 0</fdir1>
                <slip1>0</slip1>
                <slip2>0</slip2>
              </ode>
              <torsional>
                <coefficient>1</coefficient>
                <patch_radius>0</patch_radius>
                <surface_radius>0</surface_radius>
                <use_patch_radius>1</use_patch_radius>
                <ode>
                  <slip>0</slip>
                </ode>
              </torsional>
            </friction>
            <bounce>
              <restitution_coefficient>0</restitution_coefficient>
              <threshold>1e+06</threshold>
            </bounce>
            <contact>
              <collide_without_contact>0</collide_without_contact>
              <collide_without_contact_bitmask>1</collide_without_contact_bitmask>
              <collide_bitmask>1</collide_bitmask>
              <ode>
                <soft_cfm>0</soft_cfm>
                <soft_erp>0.2</soft_erp>
                <kp>1e+13</kp>
                <kd>1</kd>
                <max_vel>0.01</max_vel>
                <min_depth>0</min_depth>
              </ode>
              <bullet>
                <split_impulse>1</split_impulse>
                <split_impulse_penetration_threshold>-0.01</split_impulse_penetration_threshold>
                <soft_cfm>0</soft_cfm>
                <soft_erp>0.2</soft_erp>
                <kp>1e+13</kp>
                <kd>1</kd>
              </bullet>
            </contact>
          </surface>
        </collision>
      </link>
      <static>0</static>
      <allow_auto_disable>1</allow_auto_disable>
      <pose frame=''>-3.55297 0.01694 0.502047 -3.8e-05 0.00441 0.000115</pose>
    </model>
  </world>
</sdf>
